Workbook

Sheet Read Me
A1: OIL-PMS — Procurement Process Flow Workbook
A2: Osman Interlinings Limited (OIL) · Source: Comprehensive Procurement Process & Automation Specification, OIL-PMS-BRD-001 v1.0 (Proposed / For Review), 11 October 2026
A4: What this workbook is
A5: A plain-language map of OIL's proposed procurement process — from a purchase requisition to LC opening after the supplier's Proforma Invoice (PI) is validated — showing every step, who does it, who approves it, what is produced and what happens when something goes wrong.
A6: SCOPE: stages 01–21 follow the specification's numbering; stage 22 covers LC opening after a validated PI. Shipment, customs clearance, goods receipt (GRN), invoice matching and payment are outside this workbook. The specification does not detail the LC-opening procedure itself, so stage 22 records only what it states.
A7: It describes a PROPOSED target-state process. Approval limits and several policy choices are not yet confirmed by OIL; they are listed on the 'Open Policy Items' sheet.
A8: Process owner: Procurement Department. Stakeholders: Marketing, Store, Quality Assurance (QA), Procurement, Finance & Accounts, Import / Logistics, Executive Director (ED) / Delegated Final Approver, Suppliers, IT.
A10: How to read it — start with these three sheets
A11: 1. Process Map | B11: One page: all 22 stages across the top, every role down the side. The letter in each cell shows that role's responsibility for that stage.
A12: 2. Process Flow | B12: The master register: one row per stage with actions, checks, output, what happens next and what happens if it fails.
A13: 3. Decision Gates | B13: The 8 points where a file can move forward or be sent back, and where it goes back to.
A15: Responsibility codes used on the Process Map and Process Flow
A16: R | B16: Responsible — does the work / owns the stage
A17: A | B17: Approves / decides — takes the go / no-go decision
A18: R/A | B18: Does the work and takes the decision
A19: C | B19: Contributes — provides input (e.g. supplier sends samples or a PI)
A20: I | B20: Informed — receives an automatic system notification
A21: (blank) | B21: Not involved, or the specification does not state a role
A22: Codes are taken from the stage register (§3), process instructions (§4), approval matrix (§8), event matrix (§11) and role table (§14) of the specification. Where the specification is silent, the cell is left blank rather than assumed.
A24: Sheet index
A25: Sheet | B25: What it shows | C25: Rows | D25: Use it to…
A26: Process Map | B26: 22 stages × 9 roles responsibility matrix | C26: =COUNT('Process Map'!5:5) -> 22 | D26: See who is involved at each stage at a glance
A27: Process Flow | B27: Master step-by-step register | C27: =COUNT('Process Flow'!A:A) -> 22 | D27: Understand each stage in detail
A28: Decision Gates | B28: Go / return rules at the 8 decision points | C28: =COUNTA('Decision Gates'!A5:A12) -> 8 | D28: Know where a file goes when it fails a check
A29: Approval Matrix | B29: Marketing ACK → Finance APP → ED final APP | C29: =COUNTA('Approval Matrix'!A5:A7) -> 3 | D29: Know what each approver checks
A30: Roles & SoD | B30: What each role may and may not do | C30: =COUNTA('Roles & SoD'!A5:A15) -> 11 | D30: Check segregation of duties
A31: RFQ & Deadlines | B31: China calendar deadline rules and link states | C31: =COUNTA('RFQ & Deadlines'!A5:A11) -> 7 | D31: Set and explain RFQ deadlines
A32: Supplier Portal Fields | B32: Every field a supplier fills in | C32: =COUNTA('Supplier Portal Fields'!B5:B47) -> 43 | D32: Design the quotation form
A33: Selection & Scoring | B33: Comparison dimensions, gates and illustrative weights | C33: =COUNTA('Selection & Scoring'!A5:A10) -> 6 | D33: Evaluate bids consistently
A34: PO, PI & LC | B34: PO content, dispatch logic, PI match, PI-to-LC steps | C34: =COUNTA('PO, PI & LC'!B5:B22) -> 18 | D34: Check POs and PIs, and track LC opening
A35: Notifications | B35: 14 automated events and recipients | C35: =COUNTA(Notifications!B5:B18) -> 14 | D35: See who gets told what, when
A36: Email Templates | B36: 8 copy-ready email formats (A–H) | C36: =COUNTA('Email Templates'!A5:A12) -> 8 | D36: Configure system emails
A37: Exceptions | B37: 13 exception scenarios and owners | C37: =COUNTA(Exceptions!A5:A17) -> 13 | D37: Handle problems the same way every time
A38: KPIs & Dashboards | B38: 6 KPI formulas and dashboard contents | C38: =COUNTA('KPIs & Dashboards'!A5:A10) -> 6 | D38: Monitor the process
A39: Records & IDs | B39: 12 record types and their numbering | C39: =COUNTA('Records & IDs'!A5:A16) -> 12 | D39: Trace any transaction
A40: Open Policy Items | B40: 12 decisions OIL must confirm (to be filled in) | C40: =COUNTA('Open Policy Items'!B5:B16) -> 12 | D40: Track policy sign-off
A41: Acceptance Tests | B41: 19 software test cases | C41: =COUNTA('Acceptance Tests'!A5:A23) -> 19 | D41: Test the system before go-live
A42: Screen Map | B42: Proposed system navigation | C42: =COUNTA('Screen Map'!A5:A12) -> 8 | D42: Brief the software team
A43: Row counts are live formulas reading each sheet (green = link to another sheet).
A45: Glossary
...

Sheet Process Map
A1: Process Map — who does what at each of the 22 stages
A2: R = responsible · A = approves / decides · R/A = both · C = contributes input · I = informed by automatic notification · blank = not involved / not stated
A4: Phase | B4: Requisition | E4: Sourcing & RFQ | K4: Evaluation | N4: Negotiation & award | P4: Approvals | S4: Purchase order | V4: PI & LC opening
A5: Stage no. | B5: 1 | C5: 2 | D5: 3 | E5: 4 | F5: 5 | G5: 6 | H5: 7 | I5: 8 | J5: 9 | K5: 10 | L5: 11 | M5: 12 | N5: 13 | O5: 14 | P5: 15 | Q5: 16 | R5: 17 | S5: 18 | T5: 19 | U5: 20 | V5: 21 | W5: 22
A6: Stage | B6: =INDEX('Process Flow'!$C:$C,MATCH(B5,'Process Flow'!$A:$A,0)) -> Purchase requisition | C6: =INDEX('Process Flow'!$C:$C,MATCH(C5,'Process Flow'!$A:$A,0)) -> Requisition consolidation | D6: =INDEX('Process Flow'!$C:$C,MATCH(D5,'Process Flow'!$A:$A,0)) -> Requisition verification | E6: =INDEX('Process Flow'!$C:$C,MATCH(E5,'Process Flow'!$A:$A,0)) -> RFQ preparation | F6: =INDEX('Process Flow'!$C:$C,MATCH(F5,'Process Flow'!$A:$A,0)) -> Supplier selection (shortlist) | G6: =INDEX('Process Flow'!$C:$C,MATCH(G5,'Process Flow'!$A:$A,0)) -> Per-supplier secure link generation | H6: =INDEX('Process Flow'!$C:$C,MATCH(H5,'Process Flow'!$A:$A,0)) -> RFQ invitation email | I6: =INDEX('Process Flow'!$C:$C,MATCH(I5,'Process Flow'!$A:$A,0)) -> Supplier quotation entry | ... W6: =INDEX('Process Flow'!$C:$C,MATCH(W5,'Process Flow'!$A:$A,0)) -> LC opening (after validated PI) | X6: R count | Y6: A count | Z6: C count | AA6: I count
A7: Marketing | B7: R | D7: I | L7: R | M7: R/A | P7: A | X7: =COUNTIF(B7:W7,"*R*") -> 3 | Y7: =COUNTIF(B7:W7,"*A*") -> 2 | Z7: =COUNTIF(B7:W7,"C") -> 0 | AA7: =COUNTIF(B7:W7,"I") -> 1
A8: Store | B8: R | D8: I | X8: =COUNTIF(B8:W8,"*R*") -> 1 | Y8: =COUNTIF(B8:W8,"*A*") -> 0 | Z8: =COUNTIF(B8:W8,"C") -> 0 | AA8: =COUNTIF(B8:W8,"I") -> 1
A9: Procurement | B9: I | C9: R | D9: R/A | E9: R | F9: R | I9: I | J9: A | K9: R | L9: I | M9: I | N9: R | O9: R | P9: C | Q9: C | R9: C | S9: I | T9: I | U9: I | V9: R | X9: =COUNTIF(B9:W9,"*R*") -> 8 | Y9: =COUNTIF(B9:W9,"*A*") -> 2 | Z9: =COUNTIF(B9:W9,"C") -> 3 | AA9: =COUNTIF(B9:W9,"I") -> 7
A10: System (OIL-PMS) | G10: R | H10: R | J10: R | K10: R | S10: R | T10: R | X10: =COUNTIF(B10:W10,"*R*") -> 6 | Y10: =COUNTIF(B10:W10,"*A*") -> 0 | Z10: =COUNTIF(B10:W10,"C") -> 0 | AA10: =COUNTIF(B10:W10,"I") -> 0
A11: Supplier | H11: I | I11: R | J11: I | L11: C | N11: C | T11: I | U11: R | V11: C | X11: =COUNTIF(B11:W11,"*R*") -> 2 | Y11: =COUNTIF(B11:W11,"*A*") -> 0 | Z11: =COUNTIF(B11:W11,"C") -> 3 | AA11: =COUNTIF(B11:W11,"I") -> 3
A12: QA / Technical | L12: R | M12: R/A | X12: =COUNTIF(B12:W12,"*R*") -> 2 | Y12: =COUNTIF(B12:W12,"*A*") -> 1 | Z12: =COUNTIF(B12:W12,"C") -> 0 | AA12: =COUNTIF(B12:W12,"I") -> 0
A13: Finance & Accounts | Q13: A | V13: R | W13: A | X13: =COUNTIF(B13:W13,"*R*") -> 1 | Y13: =COUNTIF(B13:W13,"*A*") -> 2 | Z13: =COUNTIF(B13:W13,"C") -> 0 | AA13: =COUNTIF(B13:W13,"I") -> 0
A14: ED / Delegated final approver | R14: A | X14: =COUNTIF(B14:W14,"*R*") -> 0 | Y14: =COUNTIF(B14:W14,"*A*") -> 1 | Z14: =COUNTIF(B14:W14,"C") -> 0 | AA14: =COUNTIF(B14:W14,"I") -> 0
A15: Import / Logistics | V15: R | W15: R | X15: =COUNTIF(B15:W15,"*R*") -> 2 | Y15: =COUNTIF(B15:W15,"*A*") -> 0 | Z15: =COUNTIF(B15:W15,"C") -> 0 | AA15: =COUNTIF(B15:W15,"I") -> 0
A16: Roles involved | B16: =COUNTA(B7:B15) -> 3 | C16: =COUNTA(C7:C15) -> 1 | D16: =COUNTA(D7:D15) -> 3 | E16: =COUNTA(E7:E15) -> 1 | F16: =COUNTA(F7:F15) -> 1 | G16: =COUNTA(G7:G15) -> 1 | H16: =COUNTA(H7:H15) -> 2 | I16: =COUNTA(I7:I15) -> 2 | ... W16: =COUNTA(W7:W15) -> 2 | X16: =SUM(X7:X15) -> 25 | Y16: =SUM(Y7:Y15) -> 8 | Z16: =SUM(Z7:Z15) -> 6 | AA16: =SUM(AA7:AA15) -> 12
A17: Primary owner (from Process Flow) | B17: =INDEX('Process Flow'!$D:$D,MATCH(B$5,'Process Flow'!$A:$A,0)) -> Marketing / Store | C17: =INDEX('Process Flow'!$D:$D,MATCH(C$5,'Process Flow'!$A:$A,0)) -> Procurement | D17: =INDEX('Process Flow'!$D:$D,MATCH(D$5,'Process Flow'!$A:$A,0)) -> Procurement reviewer | E17: =INDEX('Process Flow'!$D:$D,MATCH(E$5,'Process Flow'!$A:$A,0)) -> Procurement | F17: =INDEX('Process Flow'!$D:$D,MATCH(F$5,'Process Flow'!$A:$A,0)) -> Procurement | G17: =INDEX('Process Flow'!$D:$D,MATCH(G$5,'Process Flow'!$A:$A,0)) -> System | H17: =INDEX('Process Flow'!$D:$D,MATCH(H$5,'Process Flow'!$A:$A,0)) -> System | I17: =INDEX('Process Flow'!$D:$D,MATCH(I$5,'Process Flow'!$A:$A,0)) -> Supplier | ... W17: =INDEX('Process Flow'!$D:$D,MATCH(W$5,'Process Flow'!$A:$A,0)) -> Import / Logistics
A19: How to read: go down a column to see everyone involved in that stage; go across a row to see everything one role does. Counts on the right show how many stages each role does (R), decides (A), contributes to (C) or is notified of (I).
A20: Approval stages 15–17 are sequential: Marketing ACK must be recorded before Finance can act, and Finance APP before the ED. Procurement prepares and supports each approval (C) and receives returned files.
A21: Stage 21: Procurement, Import and Finance share PI verification. Stage 22 (LC opening): Import / Logistics prepares; finance control applies — the specification does not name the LC approver (policy). 'ED' may be MD or another authorized delegate — Open Policy Item 1.

Sheet Process Flow
A1: Process Flow — master register of the 22 stages (requisition to LC opening)
A2: One row per stage, in sequence. Gold rows mark the seven phases. Filter on any column (row 4).
A4: Step | B4: Phase | C4: Stage | D4: Primary owner (does it) | E4: Decides / approves | F4: Contributes input | G4: Informed (auto-notified) | H4: Input / trigger | I4: Key actions | J4: Checks & controls | K4: Output / hand-off | L4: Record ID / status | M4: If OK → next step | N4: If not OK → goes to | O4: Exceptions | P4: Email template | Q4: Spec ref.
A5: Phase A — Requisition (stages 01–03)
A6: 1 | B6: Requisition | C6: Purchase requisition | D6: Marketing / Store | E6: — | F6: — | G6: Procurement | H6: Material requirement | I6: Select RM item / specification (or propose a new item); enter quantity / UOM, desired delivery date, delivery location, business justification, intended use, urgency; attach documents | J6: Mandatory-field completeness; user authorization; active item master; duplication warning; visibility of available stock and pending POs | K6: Draft / submitted PR with item, quantity, required date, reason and attachment | L6: PR-YYYY-NNNNN · status Submitted | M6: 02 Consolidation | N6: — | O6: Missing specifications return to originator; urgency flag does not bypass approval | P6: — | Q6: §3, §4-01
A7: 2 | B7: Requisition | C7: Requisition consolidation | D7: Procurement | E7: — | F7: — | G7: — | H7: Submitted PRs | I7: View open PRs together; group compatible demand by item, technical specification, shipment window and delivery location; optionally split a PR across RFQs | J7: Preserve original PR-to-line mapping and quantities; prevent double allocation; separate incompatible specifications | K7: Consolidated demand batch traceable to every origin PR and department | L7: CB-YYYY-NNNNN | M7: 03 Verification | N7: — | O7: — | P7: — | Q7: §3, §4-02
A8: 3 | B8: Requisition | C8: Requisition verification | D8: Procurement reviewer | E8: Procurement reviewer | F8: — | G8: Marketing, Store | H8: Consolidated demand | I8: Validate specifications, quantity, stock, open orders, supplier feasibility, intended procurement route and requirement date | J8: Reviewer should not silently alter approved technical specifications | K8: Verified or returned requisition; specification and stock checks recorded | L8: Validated / Returned (with reason) | M8: 04 RFQ preparation | N8: Return → 01 Requisition (originator) | O8: — | P8: — | Q8: §3, §4-03
A9: Phase B — Sourcing & RFQ (stages 04–09)
A10: 4 | B10: Sourcing & RFQ | C10: RFQ preparation | D10: Procurement | E10: — | F10: — | G10: — | H10: Verified demand | I10: Define line items, required specs, bid currency / unit, target quantity, delivery location, quality documents, sampling requirement, bid cut-off and quotation conditions | J10: Change after publish issues an RFQ revision and notifies relevant suppliers | K10: Numbered RFQ with item specification, response terms and deadline policy | L10: RFQ-YYYY-NNNNN · version V1 · Ready to Publish | M10: 05 Supplier selection | N10: — | O10: — | P10: — | Q10: §3, §4-04
A11: 5 | B11: Sourcing & RFQ | C11: Supplier selection (shortlist) | D11: Procurement | E11: — | F11: — | G11: — | H11: RFQ ready | I11: Choose active, eligible manufacturers / traders; assign vendor-country calendar and verified email contacts; document single-source situations | J11: Tax / business registration where required; sanction / compliance checks under company policy; previous performance and supplier status | K11: Invited supplier list with invitation eligibility and rationale | L11: Supplier IDs SUP-NNNNN | M11: 06 Secure link generation | N11: — | O11: Single source → documented justification and approval | P11: — | Q11: §3, §4-05
A12: 6 | B12: Sourcing & RFQ | C12: Per-supplier secure link generation | D12: System | E12: — | F12: — | G12: — | H12: Published RFQ + invited suppliers | I12: Create a random, high-entropy, supplier-specific token bound to RFQ / version / vendor; store only its hash; give individual access to that vendor's RFQ only | J12: HTTPS; token expiry; rate limits; access logs; revocation; no competitor visibility; optional one-time email verification / OTP; no sensitive prices in URL parameters | K12: Expiring submission link and per-supplier deadline for each recipient | L12: Link state: Invitation queued | M12: 07 RFQ invitation email | N12: — | O12: — | P12: — | Q12: §3, §4-06, §6
A13: 7 | B13: Sourcing & RFQ | C13: RFQ invitation email | D13: System | E13: — | F13: — | G13: Supplier | H13: Valid links | I13: Send branded invitation with subject, RFQ details, due time in supplier timezone, instructions and secure link | J13: Supplier email validation; queued / sent / failed status; retry with idempotency (no duplicate invitations) | K13: Transmission log and copy of every email | L13: Link state: Sent | M13: 08 Supplier quotation entry | N13: Send failure → retry / alert | O13: — | P13: A — RFQ invitation | Q13: §3, §4-07
A14: 8 | B14: Sourcing & RFQ | C14: Supplier quotation entry | D14: Supplier | E14: — | F14: — | G14: Procurement | H14: Supplier opens link | I14: Confirm company / contact details; enter line-wise offer and technical details; upload documents and sample schedule; save draft; sign declaration and submit | J14: Required fields; numeric ranges and units; allowed document types; antivirus scan; supplier country / timezone; version; RFQ deadline. Drafts are not evaluated | K14: Immutable submitted quotation revision | L14: QUO-YYYY-NNNNN · link states Viewed → Draft started → Submitted | M14: 09 Deadline control | N14: Mandatory field missing → final submit blocked | O14: Post-submission revision → new timestamped version | P14: C — Submission confirmation | Q14: §3, §4-08, §5
A15: 9 | B15: Sourcing & RFQ | C15: Deadline / submission control | D15: System | E15: Authorized Procurement manager (extensions) | F15: — | G15: Supplier | H15: Supplier submits or deadline reached | I15: Check server receipt time against the calculated deadline; send reminder; disable final submission at cut-off unless an extension is approved | J15: Authoritative server time, not browser / device clock; extension reason, approver and notifications recorded | K15: Timestamped submission, or closed / extended RFQ | L15: Submitted on Time / Not Submitted–Expired / Extended | M15: 10 Comparative statement | N15: Expired → close link, or approved extension → back to 08 | O15: No supplier submits → flag no-bid; re-tender / extend by authorization | P15: B — Reminder · D — Extension · E — Closure | Q15: §3, §4-09, §6
A16: Phase C — Evaluation (stages 10–12)
A17: 10 | B17: Evaluation | C17: Comparative statement (CS) | D17: System / Procurement | E17: — | F17: — | G17: — | H17: Valid received quotations | I17: Compare quotes line by line; normalize currency and UOM on dated, controlled FX; compare Incoterms on a defined landed-cost basis; show technical compliance and blanks | J17: Lowest unit price is not automatically the lowest landed cost; estimates disclosed separately from supplier-confirmed figures | K17: Versioned CS, supplier comparison and shortlist for testing / negotiation | L17: CS-YYYY-NNNNN | M17: 11 Sampling and testing | N17: — | O17: Only one responsive supplier → record sole quote and justification | P17: — | Q17: §3, §4-10, §7
A18: 11 | B18: Evaluation | C18: Sample collection and testing | D18: QA / Marketing | E18: — | F18: Supplier | G18: Procurement | H18: Sample required | I18: Request and track samples, courier / AWB, receipt, lab test plan, controlled result uploads; appearance, fusing / bond strength and other item-specific tests | J18: Approved sample waiver or alternate evidence needs its own authorization | K18: Sample register and test report with evidence | L18: SMP-YYYY-NNNNN | M18: 12 Technical acceptance | N18: — | O18: — | P18: — | Q18: §3, §4-11
A19: 12 | B19: Evaluation | C19: Technical acceptance decision | D19: QA / Marketing | E19: QA / Marketing | F19: — | G19: Procurement | H19: Completed technical assessment | I19: Decide Pass, Conditional Pass, Fail or Waived by Approval against documented tolerance / specification | J19: Conditional pass cannot be treated as a full pass without an approved deviation; failed offer blocked from award | K19: Technical clearance for negotiation / award; rejected offers archived | L19: Pass / Conditional Pass / Fail / Waived by Approval | M19: 13 Negotiation | N19: Fail → back to 10 CS (quote ineligible; clarification / re-sourcing) | O19: — | P19: — | Q19: §3, §4-12
A20: Phase D — Negotiation & award (stages 13–14)
A21: 13 | B21: Negotiation & award | C21: Commercial negotiation | D21: Procurement | E21: — | F21: Supplier | G21: — | H21: Technically qualified offers | I21: Track rounds for price, discounts, MOQ, payment, shipment, packing, Incoterms and quality undertakings; request a formal revised quotation where material | J21: Immutable original quotation; revision numbers; maker / checker rights; audit log | K21: Agreed commercial terms; old quote versions kept | L21: NEG-YYYY-NNNNN | M21: 14 Recommendation | N21: — | O21: — | P21: — | Q21: §3, §4-13
A22: 14 | B22: Negotiation & award | C22: Supplier award recommendation | D22: Procurement | E22: — | F22: — | G22: — | H22: Final offers + evaluations | I22: Prepare final CS, technical summary, total estimated landed cost, risk notes, negotiation savings and recommended vendor with written rationale | J22: Recommendation includes preferred supplier, rationale and an alternative (Gate 4) | K22: Award recommendation package for sequential acknowledgment / approval | L22: AWD-YYYY-NNNNN | M22: 15 Marketing ACK | N22: — | O22: — | P22: H — Internal approval | Q22: §3, §4-14, §7
A23: Phase E — Approvals (stages 15–17)
A24: 15 | B24: Approvals | C24: Marketing acknowledgment (ACK) | D24: Marketing | E24: Marketing | F24: Procurement | G24: — | H24: Recommendation | I24: Review fit to requested materials, operational need, quantities, approved sample / QA outcome and delivery suitability | J24: Acknowledgment is not the final financial approval; remarks recorded | K24: ACK, or return with recorded remarks | L24: Acknowledge / Return for Clarification | M24: 16 Finance APP | N24: Return → 13 Negotiation | O24: — | P24: H — Internal approval | Q24: §3, §4-15, §8
A25: 16 | B25: Approvals | C25: Finance approval (APP) | D25: Finance & Accounts | E25: Finance & Accounts | F25: Procurement | G25: — | H25: Marketing ACK | I25: Review budget, cash requirement, FX exposure, duty / freight assumptions, bank charges, payment terms, advance / LC exposure, landed cost and justification | J25: Approval thresholds enforced by the system where they apply (thresholds TBD by OIL) | K25: Timestamped decision and finance comments | L25: Approve / Return / Reject | M25: 17 ED final approval | N25: Return / reject → 13 Negotiation | O25: — | P25: H — Internal approval | Q25: §3, §4-16, §8
A26: 17 | B26: Approvals | C26: ED / final approval | D26: ED / delegated authority | E26: ED / delegated authority | F26: Procurement | G26: — | H26: Finance approval | I26: Review end-to-end award case, supplier recommendation, prior approvals, deviations and material exposures | J26: Delegation must be documented; final approval locks supplier, quantity, rates, currency, Incoterms, payment and shipment commitments | K26: Final approval, or documented return / rejection | L26: Final Approve / Return / Reject | M26: 18 Auto-generate PO | N26: Return / reject → 13 Negotiation | O26: — | P26: H — Internal approval | Q26: §3, §4-17, §8
A27: Phase F — Purchase order (stages 18–20)
A28: 18 | B28: Purchase order | C28: Automatic PO creation | D28: System | E28: — | F28: — | G28: Procurement | H28: Final approval | I28: Generate PO directly from approved fields; attach terms and technical annexures; create versioned PDF; archive checksum / snapshot | J28: Validate vendor email, ship-to / bill-to, UOM / qty, price / currency, tolerance, payment, delivery, Incoterms named location, signatures or approval reference | K28: PO ready to dispatch | L28: PO-YYYY-NNNNN · Ready to Dispatch | M28: 19 PO email | N28: Validation failure → correction queue (never sent incomplete) | O28: Material change after Finance / ED approval → freeze send, route for reapproval | P28: — | Q28: §3, §4-18, §9
A29: 19 | B29: Purchase order | C29: Automatic PO email | D29: System | E29: — | F29: — | G29: Supplier, Procurement | H29: PO validation passed | I29: Email PDF and secure acknowledgment link to the selected supplier; log send result; retry technical failures | J29: No duplicate PO numbers on retry; dispatch only when all automatic-dispatch conditions are true | K29: Sent PO PDF, message log, delivery-failure tracking | L29: PO Sent / PO Delivery Failed | M29: 20 Supplier PO ACK | N29: Failure → alert to Procurement, safe retry | O29: PO email failed → hold, alert, safe retry | P29: F — Official PO | Q29: §3, §4-19, §9
A30: 20 | B30: Purchase order | C30: Supplier PO acknowledgment | D30: Supplier | E30: Supplier | F30: — | G30: Procurement | H30: PO email / secure link | I30: Open link; accept the PO or flag a specific discrepancy | J30: Supplier cannot modify the PO; dispute creates a change-request task, with possible reapproval; reminder and escalation if pending | K30: Accepted or disputed PO with timestamp and identity | L30: Accepted / Disputed / Awaiting Acknowledgment | M30: 21 PI receipt | N30: Dispute → 13 Negotiation (change request) | O30: Supplier disputes PO → stop PI progression until resolved | P30: G — PO ACK reminder | Q30: §3, §4-20, §9
A31: Phase G — PI & LC opening (stages 21–22)
A32: 21 | B32: PI & LC opening | C32: PI receipt and verification | D32: Procurement / Import / Finance | E32: — | F32: Supplier | G32: — | H32: Supplier PO acceptance | I32: Collect PI; compare seller / buyer, material / specs, HS code where available, quantity, unit price, total, currency, Incoterms / place, shipping schedule, payment and bank details | J32: Bank-detail change needs independent verification; differences create documented exceptions; no silent acceptance of mismatched terms | K32: PO–PI comparison with exceptions resolved | L32: PI-YYYY-NNNNN · PI Matched / Approved for Import Processing | M32: 22 Import, shipment & GRN | N32: Mismatch → clarification / change request → 21 | O32: PO vs PI mismatch → prevent unapproved payment flow; vendor bank change → dual control | P32: — | Q32: §3, §4-21, §9
A33: 22 | B33: PI & LC opening | C33: LC opening (after validated PI) | D33: Import / Logistics | E33: Finance control — LC approval per OIL policy (approver not named in the specification) | F33: — | G33: — | H33: PI Matched / Approved for Import Processing | I33: Apply the applicable bank / LC process: import documentation and banking checks, then LC approval per policy, then LC opening against the validated PI | J33: Import cannot bypass finance control; LC / advance exposure already reviewed at Finance APP (stage 16); PO vs PI mismatch prevents unapproved payment flow; changed vendor bank details need independent verification and dual control | K33: LC opened against the validated PI and approved PO | L33: No LC record ID defined in the specification (to confirm) | M33: End of this process scope | N33: Exception case / change request → back to 21 | O33: Material change after Finance / ED approval → freeze and route for reapproval | P33: — | Q33: §4-22, §10, §14, §17
A35: Columns E–G follow the codes on the Process Map (A, C, I). '—' means the specification names no role for that column. Record IDs follow the pattern on the 'Records & IDs' sheet.

Sheet Decision Gates
A1: Decision Gates — where a file moves forward or is sent back
A2: A file moves forward only when its gate is passed; otherwise it returns to a named owner with a recorded reason
A4: Stage | B4: Gate | C4: Decided by | D4: If passed → next | E4: If not passed → back to
A5: 03 | B5: Requisition validation | C5: Procurement reviewer | D5: Accept → 04 RFQ preparation | E5: Return → 01 Requisition, with reason
A6: 09 | B6: Deadline / submission control | C6: System; extensions by authorized Procurement manager | D6: Valid submission → 10 Comparative statement | E6: Expired → close link, or approved extension → 08 Supplier quote entry
A7: 12 | B7: Technical acceptance | C7: QA / Marketing | D7: Pass / approved waiver → 13 Negotiation | E7: Fail → 10 Comparative statement
A8: 15 | B8: Marketing ACK | C8: Marketing | D8: ACK → 16 Finance APP | E8: Return → 13 Negotiation
A9: 16 | B9: Finance APP | C9: Finance & Accounts | D9: Approve → 17 ED final APP | E9: Return / reject → 13 Negotiation
A10: 17 | B10: ED final APP | C10: ED / delegated authority | D10: Approve → 18 Auto-generate PO | E10: Return / reject → 13 Negotiation
A11: 20 | B11: Supplier PO ACK | C11: Supplier | D11: Accepted → 21 PI receipt | E11: Dispute → 13 Negotiation (change request)
A12: 21 | B12: PI validation | C12: Procurement / Import / Finance | D12: Matched → 22 LC opening | E12: Mismatch → clarification / change request → 21
A14: Common status rules (apply at every gate)
B15: Status | C15: Rule
B16: Return | C16: Sends the file to a named prior owner with a mandatory reason; returned items never appear as approved.
B17: Reject | C17: Ends the current approval attempt; resubmission requires a revision or newly approved exception.
B18: Cancel | C18: A separately authorized end state with reason and audit history.
B19: Change after approval | C19: Triggers a versioned change request and re-approval per authority matrix — never an invisible overwrite.

Sheet Approval Matrix
A1: Approval Matrix — sequential approval and change governance
A2: Marketing ACK → Finance APP → ED / delegated final APP. Financial limits and alternate approvers: TBD by OIL (configurable rules).
A4: Stage | B4: Approval | C4: Approver | D4: Primary decision | E4: Evidence expected | F4: Return path
A5: 15 | B5: Marketing ACK | C5: Marketing | D5: Need / quantity / spec / sample suitability | E5: PR, technical result, CS, proposed delivery | F5: Procurement negotiation / QA
A6: 16 | B6: Finance APP | C6: Finance & Accounts | D6: Affordability, cost, exposure, payment terms | E6: Landed-cost sheet, budget, FX, LC / TT / advance implications | F6: Procurement for revision
A7: 17 | B7: ED / delegated final APP | C7: ED / delegated authority | D7: Final commercial award authority | E7: Full award pack, deviation register, prior approvals | F7: Procurement / Finance as relevant
A9: Mandatory workflow principles
A10: 1 | B10: One named accountable reviewer per step
A11: 2 | B11: Delegated authority only under a maintained matrix
A12: 3 | B12: No self-approval where segregation applies
A13: 4 | B13: Decision remarks and timestamp on every decision
A14: 5 | B14: No skipped step without an authorized policy exception
A15: 6 | B15: Stepwise notification and escalation
A16: 7 | B16: Immutable version of the decision pack
A17: 8 | B17: Approval financial limits and alternate approvers are TBD by OIL — stored as configurable rules, no BDT amount assumed
A19: Material changes — any change to these after approval requires review / reapproval
A20: 1 | B20: Supplier
A21: 2 | B21: Unit price
A22: 3 | B22: Currency
A23: 4 | B23: Ordered quantity
A24: 5 | B24: Incoterms
A25: 6 | B25: Payment terms
A26: 7 | B26: Delivery commitment
A27: 8 | B27: Significant quality deviations

Sheet Roles & SoD
A1: Roles & Segregation of Duties — role-based access
A2: No one who prepares a transaction can approve it alone; privileged actions are audited separately
A4: Role | B4: Create / edit | C4: Review / approve | D4: Restricted actions
A5: Marketing requester | B5: Own requisitions; technical feedback | C5: Marketing ACK if assigned | D5: Cannot issue final PO
A6: Store requester / receiver | B6: Own PR; GRN receipts | C6: Receipt verification | D6: Cannot approve supplier invoices independently
A7: Procurement executive | B7: RFQs, supplier invites, CS, negotiations, recommendation | C7: Workflow preparation | D7: Cannot self-final-approve award
A8: Procurement supervisor | B8: Validate sourcing / review | C8: Assigned Procurement review | D8: Cannot change final-approved PO silently
A9: Supplier | B9: Only own RFQ response and PO acknowledgment | C9: None internally | D9: Cannot view rivals' bids, internal scoring or approvals
A10: QA / Technical | B10: Sample / testing data | C10: Technical pass / fail or waiver under authority | D10: Cannot edit supplier bid price
A11: Finance & Accounts | B11: Budget / cost / payment data | C11: Finance APP and payment authorization per role | D11: Cannot alter technical test results
A12: ED / final approver | B12: Review package | C12: Final supplier / award APP | D12: Changes require documented amendment
A13: Import / Logistics | B13: Shipping, PI checks, LC / TT documents | C13: Operational verifications | D13: Cannot bypass finance control
A14: System administrator | B14: Configuration, roles and support | C14: No commercial approvals by default | D14: Privileged actions separately audited
A15: Internal audit / MD dashboard viewer | B15: Read-only authorized reporting | C15: None unless explicitly delegated | D15: No transactional edits

Sheet RFQ & Deadlines
A1: RFQ & Deadlines — China deadline engine and secure link states
A2: Proposed default policy. These values are configuration, not hard-coded policy (counting convention and closing hour: Open Policy Items 2–3).
A4: Setting | B4: Proposed default
A5: Standard RFQ response window | B5: 3 China working days
A6: Urgent RFQ response window | B6: 2 China working days, with authorized reason
A7: Counting starts | B7: Next China working day after invitation / publish
A8: Closing time | B8: 17:00 China Standard Time (Asia/Shanghai, UTC+08:00) on the last counted working day = 15:00 Bangladesh time
A9: Reminder | B9: One China working day before close, to non-submitters
A10: Default supplier calendar | B10: CN (China) for China-based suppliers
A11: Nature of these values | B11: Configuration, not hard-coded policy
A13: Deadline rules — in the order the system applies them
A14: Rule no. | B14: Rule
A15: 1 | B15: Confirm the supplier's country and assigned work calendar (CN by default for a China-based supplier).
A16: 2 | B16: The calendar includes Chinese public holidays and officially designated weekend make-up workdays; yearly data are maintained / verified by an administrator before use.
A17: 3 | B17: Convert all local display times to / from a UTC database timestamp. 'China CST' means China Standard Time, not US Central Standard Time.
A18: 4 | B18: closing_date = Nth eligible working date after the RFQ issue date under the counting convention; apply the configured closing hour.
A19: 5 | B19: Display the exact deadline in China time and OIL / Bangladesh time, with timezone name and UTC offset.
A20: 6 | B20: Send a reminder one China working day before close to non-submitters.
A21: 7 | B21: At cut-off, revoke final-submit ability; preserve submitted records; drafts remain historical but unsubmitted.
A22: 8 | B22: An authorized extension needs a revised due date, explanation and approver; notify the supplier and record the original deadline.
A23: 9 | B23: If the supplier country is not China, use that country's approved calendar — never assume a global Monday–Friday calendar.
A24: 10 | B24: If the holiday / calendar feed is unavailable, block uncertain deadline publication and alert Procurement — never silently compute a possibly wrong cut-off.
A26: Illustrative example (not a live calendar calculation): a China supplier invited on Monday, with Tuesday–Thursday confirmed working days, must respond by Thursday 17:00 China time (15:00 Bangladesh time). An official holiday or make-up working day may change this.
A28: Secure link states
A29: State | B29: Meaning
A30: Invitation queued | B30: Link created, email waiting to send
A31: Sent | B31: Invitation email sent and logged
A32: Viewed | B32: Supplier opened the link
A33: Draft started | B33: Supplier saved a draft (drafts are not evaluated)
A34: Submitted | B34: Final submission received before the deadline
A35: Not submitted → Expired | B35: Deadline passed without a submission; link inactive
A36: Deadline extended → Submitted | B36: Authorized extension, then submission
A38: Link security: random, high-entropy, supplier-bound token (only a hash stored server-side); HTTPS; token expiry; rate limits; access logs; revocation; optional email OTP; sensitive-action logging; no sensitive prices in URL parameters; a supplier never sees other suppliers' bids.

Sheet Supplier Portal Fields
A1: Supplier Portal Fields — the quotation data dictionary
A2: R = required for the relevant RM category · R where… = required only where it applies · C = conditional. The RFQ issuer sets exact mandatory fields per material family.
A4: No. | B4: Section | C4: Field / parameter | D4: Type | E4: Rule / purpose
A5: 1 | B5: Identity | C5: Legal supplier name, country, registered address | D5: R | E5: Pre-filled where vendor master exists; confirm changes
A6: 2 | B6: Identity | C6: Manufacturer or trader; actual manufacturing site | D6: R | E6: Support source traceability
A7: 3 | B7: Contact | C7: Contact name, designation, email, phone | D7: R | E7: PO routing / clarification
A8: 4 | B8: Reference | C8: Supplier quotation reference and date | D8: R | E8: Quote version evidence
A9: 5 | B9: Commercial | C9: Currency, unit price, quote unit, quoted quantity | D9: R | E9: Correct UOM and price normalization
A10: 6 | B10: Commercial | C10: Tiered quantity price, discount / rebate | D10: C | E10: Compare alternate quantities
A11: 7 | B11: Commercial | C11: Minimum order quantity (MOQ) | D11: R | E11: Supply feasibility
A12: 8 | B12: Commercial | C12: Quotation validity date | D12: R | E12: Flag expiry before award
A13: 9 | B13: Commercial | C13: Payment method and detailed terms | D13: R | E13: LC sight / usance; TT advance / balance; credit days
A14: 10 | B14: Commercial | C14: Bank charges allocation | D14: C | E14: Real landed-cost and payment comparison
A15: 11 | B15: Logistics | C15: Incoterms 2020 rule and named place / port | D15: R | E15: e.g. FOB Shanghai Port, CIF Chattogram Port
A16: 12 | B16: Logistics | C16: Port of loading; discharge / destination | D16: R for import | E16: Shipment planning
... A47: 43 | B47: Declaration | C47: Authorized name, timestamp and acceptance | D47: R | E47: Digital submission record
A49: Summary by section (live counts)
B50: Section | C50: Required | D50: Required where applicable | E50: Conditional | F50: Total
B51: Identity | C51: =COUNTIFS($B$5:$B$47,$B51,$D$5:$D$47,"R") -> 2 | D51: =COUNTIFS($B$5:$B$47,$B51,$D$5:$D$47,"R *") -> 0 | E51: =COUNTIFS($B$5:$B$47,$B51,$D$5:$D$47,"C") -> 0 | F51: =SUM(C51:E51) -> 2
B52: Contact | C52: =COUNTIFS($B$5:$B$47,$B52,$D$5:$D$47,"R") -> 1 | D52: =COUNTIFS($B$5:$B$47,$B52,$D$5:$D$47,"R *") -> 0 | E52: =COUNTIFS($B$5:$B$47,$B52,$D$5:$D$47,"C") -> 0 | F52: =SUM(C52:E52) -> 1
B53: Reference | C53: =COUNTIFS($B$5:$B$47,$B53,$D$5:$D$47,"R") -> 1 | D53: =COUNTIFS($B$5:$B$47,$B53,$D$5:$D$47,"R *") -> 0 | E53: =COUNTIFS($B$5:$B$47,$B53,$D$5:$D$47,"C") -> 0 | F53: =SUM(C53:E53) -> 1
B54: Commercial | C54: =COUNTIFS($B$5:$B$47,$B54,$D$5:$D$47,"R") -> 4 | D54: =COUNTIFS($B$5:$B$47,$B54,$D$5:$D$47,"R *") -> 0 | E54: =COUNTIFS($B$5:$B$47,$B54,$D$5:$D$47,"C") -> 2 | F54: =SUM(C54:E54) -> 6
B55: Logistics | C55: =COUNTIFS($B$5:$B$47,$B55,$D$5:$D$47,"R") -> 3 | D55: =COUNTIFS($B$5:$B$47,$B55,$D$5:$D$47,"R *") -> 1 | E55: =COUNTIFS($B$5:$B$47,$B55,$D$5:$D$47,"C") -> 3 | F55: =SUM(C55:E55) -> 7
B56: Packing | C56: =COUNTIFS($B$5:$B$47,$B56,$D$5:$D$47,"R") -> 0 | D56: =COUNTIFS($B$5:$B$47,$B56,$D$5:$D$47,"R *") -> 0 | E56: =COUNTIFS($B$5:$B$47,$B56,$D$5:$D$47,"C") -> 2 | F56: =SUM(C56:E56) -> 2
B57: Technical | C57: =COUNTIFS($B$5:$B$47,$B57,$D$5:$D$47,"R") -> 1 | D57: =COUNTIFS($B$5:$B$47,$B57,$D$5:$D$47,"R *") -> 3 | E57: =COUNTIFS($B$5:$B$47,$B57,$D$5:$D$47,"C") -> 11 | F57: =SUM(C57:E57) -> 15
B58: QA documents | C58: =COUNTIFS($B$5:$B$47,$B58,$D$5:$D$47,"R") -> 0 | D58: =COUNTIFS($B$5:$B$47,$B58,$D$5:$D$47,"R *") -> 1 | E58: =COUNTIFS($B$5:$B$47,$B58,$D$5:$D$47,"C") -> 1 | F58: =SUM(C58:E58) -> 2
B59: Sample | C59: =COUNTIFS($B$5:$B$47,$B59,$D$5:$D$47,"R") -> 1 | D59: =COUNTIFS($B$5:$B$47,$B59,$D$5:$D$47,"R *") -> 0 | E59: =COUNTIFS($B$5:$B$47,$B59,$D$5:$D$47,"C") -> 2 | F59: =SUM(C59:E59) -> 3
B60: Performance | C60: =COUNTIFS($B$5:$B$47,$B60,$D$5:$D$47,"R") -> 1 | D60: =COUNTIFS($B$5:$B$47,$B60,$D$5:$D$47,"R *") -> 0 | E60: =COUNTIFS($B$5:$B$47,$B60,$D$5:$D$47,"C") -> 1 | F60: =SUM(C60:E60) -> 2
B61: Declaration | C61: =COUNTIFS($B$5:$B$47,$B61,$D$5:$D$47,"R") -> 2 | D61: =COUNTIFS($B$5:$B$47,$B61,$D$5:$D$47,"R *") -> 0 | E61: =COUNTIFS($B$5:$B$47,$B61,$D$5:$D$47,"C") -> 0 | F61: =SUM(C61:E61) -> 2
B62: Total | C62: =SUM(C51:C61) -> 16 | D62: =SUM(D51:D61) -> 5 | E62: =SUM(E51:E61) -> 22 | F62: =SUM(F51:F61) -> 43
B63: Check: total = fields listed | F63: =IF(F62=COUNTA(C5:C47),"OK","CHECK") -> OK
A65: Portal screens: Grouped tabs (Company, Commercial, Technical, Delivery & Packing, Sample & Documents, Review & Submit); item-wise specification template; inline validation; controlled dropdowns and units; save draft; attachments; printable submission receipt; revision history; mobile-friendly layout; supplier-specific language / timezone labels.
A66: File controls: Permitted PDF / XLSX / JPG / PNG for appropriate uses; configurable size limits; malware scanning; download authorizations; virus / quarantine outcome logging.

Sheet Selection & Scoring
A1: Selection & Scoring — comparative statement and supplier selection
A2: The lowest unit price is not automatically the lowest total landed cost
A4: No. | B4: Mandatory comparison dimension
A5: 1 | B5: Price per normalized UOM and quoted currency; FX source / date; total offer price
A6: 2 | B6: Estimated freight, insurance, bank charges, customs / tax and inland costs, if applicable — shown as estimated until confirmed
A7: 3 | B7: Incoterms / named port, payment terms, working-capital requirement and quote validity
A8: 4 | B8: Specifications and test compliance, sample status, MOQ, available stock, production / dispatch timing
A9: 5 | B9: Vendor history: delivery reliability, quality complaints / replacement responsiveness, capacity and documentation performance
A10: 6 | B10: Deviations to spec, quality and commercial conditions, and unresolved risks
A12: Suggested decision logic — five gates (policy subject to approval)
A13: Gate | B13: Name | C13: Passes when
A14: Gate 1 | B14: Eligibility | C14: Active / compliant supplier; quote received by valid deadline
A15: Gate 2 | B15: Technical qualification | C15: Tested pass or formally approved deviation / waiver
A16: Gate 3 | B16: Commercial comparison | C16: Landed cost, payment exposure and on-time supply
A17: Gate 4 | B17: Procurement recommendation | C17: Preferred supplier with rationale and alternative
A18: Gate 5 | B18: Sequential approval | C18: Marketing ACK → Finance APP → ED / Final APP
A20: Sample weighted score — ILLUSTRATIVE ONLY (Open Policy Item 7)
B21: Criterion | C21: Note | D21: Weight
B22: Cost | C22: Illustrative weight from the specification — must be approved before use | D22: 0.35
B23: Technical & Quality | C23: Illustrative weight from the specification — must be approved before use | D23: 0.3
B24: Delivery | C24: Illustrative weight from the specification — must be approved before use | D24: 0.2
B25: Commercial Terms | C25: Illustrative weight from the specification — must be approved before use | D25: 0.1
B26: Supplier History | C26: Illustrative weight from the specification — must be approved before use | D26: 0.05
B27: Total (must equal 100%) | C27: =IF(ROUND(D27,4)=1,"OK — weights total 100%","CHECK — weights do not total 100%") -> OK — weights total 100% | D27: =SUM(D22:D26) -> 1
A29: Weights cannot override mandatory QA rejection gates.
A30: Negotiated savings = baseline comparable landed cost − final comparable landed cost, shown separately from budget savings; exchange-rate effects and quantity changes stay visible rather than being attributed to negotiation.

Sheet PO, PI & LC
A1: PO, PI & LC — purchase order rules, PI check and the route to LC opening
A2: The PO is generated directly from the approved fields and emailed only when every dispatch condition is true
A4: No. | B4: PO content checklist | C4: No. | D4: PI must match the PO on
A5: 1 | B5: PO number / date | C5: 1 | D5: Buyer / seller identities
A6: 2 | B6: Buyer legal name Osman Interlinings Limited (OIL) and address | C6: 2 | D6: Description / specification
A7: 3 | B7: Supplier legal details / contact | C7: 3 | D7: Quantities
A8: 4 | B8: Delivery and invoice addresses | C8: 4 | D8: Price
A9: 5 | B9: Originating PR / RFQ / quote IDs | C9: 5 | D9: Totals
A10: 6 | B10: Material code / description / technical annex | C10: 6 | D10: Currency
A11: 7 | B11: Quantity / UOM / tolerance | C11: 7 | D11: Shipping window
A12: 8 | B12: Unit and extended amount | C12: 8 | D12: Incoterms place
A13: 9 | B13: Currency / tax assumptions | C13: 9 | D13: Payment terms
A14: 10 | B14: Incoterms 2020 named place | C14: 10 | D14: Beneficiary bank details
A15: 11 | B15: Shipment schedule and loading / discharge port
A16: 12 | B16: Packing / marking
A17: 13 | B17: Sample / quality acceptance standard
A18: 14 | B18: Payment and banking terms
A19: 15 | B19: Claims / replacement provisions
A20: 16 | B20: Required trade documents
A21: 17 | B21: Approved internal reference
A22: 18 | B22: Supplier acknowledgment instructions
A24: Automatic dispatch logic
A25: No. | B25: Condition — ALL must be true | C25: No. | D25: Then the system will
A26: 1 | B26: Final approval = valid | C26: 1 | D26: Create approved PDF
A27: 2 | B27: PO source version = final approved version | C27: 2 | D27: Enqueue email
A28: 3 | B28: Required fields complete | C28: 3 | D28: Log message ID
A29: 4 | B29: Supplier email verified | C29: 4 | D29: Track send / delivery error
A30: 5 | B30: No unresolved blocking deviations
A31: Any failed check sends the PO to a correction queue instead of the supplier. A different legal PO is never regenerated under the same identifier without a revision. The supplier can only Accept or Dispute — never modify — the PO.
A33: From PI to LC opening (stages 20–22)
A34: Step | B34: Activity | D34: Responsible
A35: 1 | B35: Supplier accepts the PO (stage 20) | D35: Supplier
A36: 2 | B36: Collect the Proforma Invoice (PI) from the supplier | D36: Procurement / Import / Finance
A37: 3 | B37: Compare the PI with the approved PO on the ten match points | D37: Procurement / Import / Finance
A38: 4 | B38: Resolve differences — documented exception or change request; independent verification of any bank-detail change | D38: Procurement / Import / Finance
A39: 5 | B39: PI Matched / Approved for Import Processing | D39: Procurement / Import / Finance
A40: 6 | B40: Import documentation / banking checks | D40: Import / Logistics
A41: 7 | B41: LC approval per policy (import cannot bypass finance control) | D41: Finance control — approver per OIL policy
A42: 8 | B42: LC opening | D42: Import / Logistics
A43: Documents at this point: Proforma Invoice (PI); Approved PO (frozen approved version); LC / TT documents; Import permission / customs documentation. Exact mandatory document rules depend on the import method and regulations; Finance / Import must validate them. Domestic purchases may bypass the LC / TT step.
...

Sheet Notifications
A1: Notifications — automated communications event matrix
A2: Automated messages come from an official OIL sender address and are archived with the related RFQ / PO
A4: Lifecycle | B4: Event | C4: Recipient | D4: Automation | E4: Key rule | F4: Template
A5: RFQ | B5: RFQ published | C5: Invited supplier | D5: RFQ email with individualized link | E5: Record send status | F5: A
A6: RFQ | B6: Deadline approaching | C6: Suppliers not yet submitted | D6: Reminder | E6: Suggested 1 supplier-country working day prior | F6: B
A7: RFQ | B7: Supplier submits | C7: That supplier + Procurement | D7: Confirmation and internal notification | E7: Keep confidential | F7: C
A8: RFQ | B8: Deadline reached | C8: Procurement; optional supplier closure notice | D8: Close submissions | E8: No late silent overwrites | F8: E
A9: RFQ | B9: Deadline extended | C9: Affected supplier | D9: Revised deadline email | E9: Authorized and logged | F9: D
A10: RFQ | B10: All bids collected / RFQ closed | C10: Procurement | D10: CS preparation alert | E10: Include missing supplier indicators | F10: —
A11: Evaluation & approval | B11: Test completed | C11: Procurement / Marketing | D11: QA outcome notice | E11: Block failed offer | F11: —
A12: Evaluation & approval | B12: Approval task assigned | C12: Marketing / Finance / ED | D12: Action email / in-app notification | E12: Role-specific access | F12: H
A13: Evaluation & approval | B13: Approval overdue | C13: Approver / escalation owner | D13: Escalation | E13: Rule configurable | F13: —
A14: Evaluation & approval | B14: Final approval recorded | C14: Procurement + system PO service | D14: Auto-PO validation / dispatch | E14: No send on failed checks | F14: —
A15: Purchase order | B15: PO sent | C15: Selected supplier | D15: Official PO email + PDF | E15: Track failed delivery | F15: F
... A18: PI & LC | B18: PI uploaded | C18: Procurement / Import / Finance | D18: Validation task | E18: PO comparison required | F18: —

Sheet Email Templates
A1: Email Templates — copy-ready formats A–H
A2: Placeholders in braces are filled from validated master / transaction data. Attachments and links must be access-controlled.
A4: Code | B4: Template | C4: Subject | D4: Body
A5: A | B5: Automated RFQ invitation | C5: Request for Quotation — {RFQ_NUMBER} | Osman Interlinings Limited (OIL) | D5: Dear {SUPPLIER_CONTACT_NAME}, Greetings from Osman Interlinings Limited (OIL). We invite your quotation for {MATERIAL_NAME} against RFQ {RFQ_NUMBER} for {QUANTITY} {UOM}. Kindly submit your pricing, Incoterms and named place, payment terms, material specifications, quality data, production/shipment lead time, sample arrangements and supporting documents through your secure supplier link. Submission link: {RFQ_LINK} Deadline: {RFQ_DEADLINE_CHINA} (China Standard Time, UTC+08:00) Reference documents: {ATTACHMENT_LIST} The link will automatically close at the stated deadline. Please complete all required fields and declare any deviation from our specification. Submission is an invitation to quote and does not constitute a purchase commitment. Best regards, Procurement Department Osman Interlinings Limited (OIL) {CONTACT_EMAIL}
A6: B | B6: RFQ reminder | C6: Reminder — RFQ {RFQ_NUMBER} Closes on {RFQ_DEADLINE_CHINA} | D6: Dear {SUPPLIER_CONTACT_NAME}, This is a reminder that your quotation for {MATERIAL_NAME} under RFQ {RFQ_NUMBER} is due by {RFQ_DEADLINE_CHINA} (China time). Please complete the submission through: {RFQ_LINK}. The secure link will expire at the deadline. If you have already submitted, please disregard this message. Best regards, Procurement Department | Osman Interlinings Limited (OIL)
A7: C | B7: Supplier submission confirmation | C7: Quotation Received — RFQ {RFQ_NUMBER} / Submission {SUBMISSION_ID} | D7: Dear {SUPPLIER_CONTACT_NAME}, Thank you. We confirm receipt of your quotation submitted on {SUBMITTED_AT} for RFQ {RFQ_NUMBER}. Your submission reference is {SUBMISSION_ID}. Status: Received — under evaluation. This acknowledgment does not constitute supplier selection or PO acceptance. Best regards, Procurement Department | Osman Interlinings Limited (OIL)
A8: D | B8: RFQ extension | C8: Revised RFQ Submission Deadline — {RFQ_NUMBER} | D8: Dear {SUPPLIER_CONTACT_NAME}, Please note that the submission deadline for RFQ {RFQ_NUMBER} has been extended to {NEW_DEADLINE_CHINA} (China time). Your secure quotation link is: {RFQ_LINK}. Please ensure that all mandatory details and documents are submitted before the revised cutoff. Best regards, Procurement Department | Osman Interlinings Limited (OIL)
A9: E | B9: RFQ closure | C9: RFQ Submission Closed — {RFQ_NUMBER} | D9: Dear {SUPPLIER_CONTACT_NAME}, The submission window for RFQ {RFQ_NUMBER} has closed at {RFQ_DEADLINE_CHINA}. The secure link is now inactive. Any request to extend or reopen an RFQ is subject to internal authorization. Thank you for your interest. Best regards, Procurement Department | Osman Interlinings Limited (OIL)
A10: F | B10: Official PO issuance (automated after approval) | C10: Official Purchase Order — {PO_NUMBER} | Osman Interlinings Limited (OIL) | D10: Dear {SUPPLIER_CONTACT_NAME}, Following the completion of our internal evaluation and approval, Osman Interlinings Limited (OIL) is pleased to issue Purchase Order {PO_NUMBER}, dated {PO_DATE}, with the following summary: - Material: {MATERIAL_NAME} - Quantity: {QUANTITY} {UOM} - Total Order Value: {CURRENCY} {PO_TOTAL} - Incoterms & Named Place: {INCOTERMS_NAMED_PLACE} - Payment Terms: {PAYMENT_TERMS} - Agreed Shipment Date/Window: {SHIPMENT_COMMITMENT} The official approved PO PDF is attached. Please review the full terms and specifications, confirm acceptance at {PO_ACK_LINK}, and submit the corresponding Proforma Invoice (PI). Any discrepancy must be raised before confirmation. Best regards, Procurement Department Osman Interlinings Limited (OIL) {CONTACT_EMAIL} Attachment: Purchase_Order_{PO_NUMBER}.pdf
A11: G | B11: PO acknowledgment reminder | C11: Action Required — Acknowledge PO {PO_NUMBER} | D11: Dear {SUPPLIER_CONTACT_NAME}, Our records show that acknowledgment of PO {PO_NUMBER} remains pending. Please review the PO and confirm acceptance or report a discrepancy at: {PO_ACK_LINK}. Kindly submit the PI consistent with the approved PO terms. Best regards, Procurement Department | Osman Interlinings Limited (OIL)
A12: H | B12: Internal approval assignment | C12: Procurement Approval Required — {REQUEST_ID} / {STAGE} | D12: Dear {APPROVER_NAME}, An OIL procurement case requires your {STAGE} action. - Reference: {REQUEST_ID} - Material: {MATERIAL_NAME} - Recommended Supplier: {SUPPLIER_NAME} - Proposed Value: {CURRENCY} {AMOUNT} - Requested Action: {ACTION_LABEL} - Review Link: {INTERNAL_APPROVAL_LINK} Please review the supporting RFQ, CS, quality record and commercial justification, then approve, return or reject with comments as applicable. OIL Procurement Management System

Sheet Exceptions
A1: Exceptions — expected system behaviour and owner
A2: Every exception is handled the same way every time, with a named owner
A4: No. | B4: Scenario | C4: Expected system behaviour | D4: Owner / authority
A5: 1 | B5: No supplier submits in time | C5: Close links; flag no-bid; re-tender / extension by authorization | D5: Procurement approver
A6: 2 | B6: Supplier requests late submission | C6: Block unless exception approval; record original / extended cut-off | D6: Authorized Procurement manager
A7: 3 | B7: China holiday schedule unavailable | C7: Halt uncertain deadline computation; request calendar verification | D7: System admin / Procurement
A8: 4 | B8: Supplier quote incomplete | C8: Save draft; block final submit for mandatory fields | D8: Supplier
A9: 5 | B9: Only one responsive supplier | C9: Record sole quote and justification; extra approval if policy requires | D9: Procurement / Management
A10: 6 | B10: Sample rejected | C10: Mark quote ineligible; trigger clarification / re-sourcing | D10: QA / Marketing
A11: 7 | B11: Incoterms quoted without named location | C11: Block completeness or flag hard exception | D11: Procurement
A12: 8 | B12: Post-submission quote revision | C12: New version with timestamp; approval / visibility rules | D12: Supplier / Procurement
A13: 9 | B13: Material change after Finance / ED approval | C13: Freeze send and route for reapproval | D13: Finance / Final approver
A14: 10 | B14: PO automatic email failed | C14: Hold status, alert owner, safe retry and send audit | D14: Procurement / IT
A15: 11 | B15: Supplier disputes PO | C15: Stop PI progression until resolution and relevant reapproval | D15: Procurement / Finance
A16: 12 | B16: PO vs PI mismatch | C16: Flag line-level discrepancy; prevent unapproved payment flow | D16: Import / Finance
A17: 13 | B17: Vendor bank details changed | C17: Independent verification and dual control before settlement | D17: Finance

Sheet KPIs & Dashboards
A1: KPIs & Dashboards — management oversight
A2: Baseline historical data and target thresholds are not supplied; reporting must not present invented savings or performance percentages
A4: KPI | B4: Formula / definition | C4: Baseline | D4: Target
A5: RFQ response rate | B5: Quotations validly submitted ÷ suppliers invited × 100 | C5: Not supplied | D5: Not supplied
A6: PR-to-PO lead time | B6: PO dispatch timestamp − initial approved PR submission timestamp | C6: Not supplied | D6: Not supplied
A7: Sample acceptance rate | B7: Samples accepted ÷ samples fully evaluated × 100 | C7: Not supplied | D7: Not supplied
A8: Quote-to-PO conversion | B8: Awarded RFQs ÷ RFQs closed and evaluated × 100 | C8: Not supplied | D8: Not supplied
A9: PO acknowledgment SLA | B9: Supplier ACK timestamp − PO email sent timestamp | C9: Not supplied | D9: Not supplied
A10: Negotiated savings | B10: Like-for-like comparable baseline cost − approved comparable final cost | C10: Not supplied | D10: Not supplied
A12: Dashboard contents
A13: Operational dashboard | C13: Management dashboard
A14: Open PRs | C14: Total procurement value
A15: Upcoming deadlines | C15: Approved vs pending orders
A16: Quotations pending | C16: Estimated landed cost by material / supplier
A17: Suppliers not responding | C17: Time from PR to RFQ
A18: Tests pending | C18: RFQ response rate
A19: Negotiation queue | C19: RFQ-to-PO cycle time
A20: Cases at each approval level | C20: Negotiated cost improvements
A21: PO email delivery failures | C21: Sample first-pass rate
A22: PIs unmatched | C22: Unacknowledged POs
C23: Exception closure time

Sheet Records & IDs
A1: Records & IDs — data entities and numbering
A2: Every record stores created_by, created_at, updated_by, updated_at, status, revision and event history. Submitted / approved documents are never overwritten without keeping prior versions.
A4: Record | B4: Identifier example | C4: Key relationships / fields | D4: Created at stage
A5: Purchase requisition | B5: PR-2026-00001 | C5: Origin department, requester, lines and dates | D5: 01
A6: Consolidation batch | B6: CB-2026-00001 | C6: PR line mapping, quantity allocations | D6: 02
A7: RFQ | B7: RFQ-2026-00001 | C7: Revision, expiry, invited supplier list | D7: 04
A8: Supplier | B8: SUP-00001 | C8: Contacts, addresses, status, bank verification | D8: 05
A9: Quotation | B9: QUO-2026-00001 | C9: RFQ ID, supplier ID, revision, commercial / technical lines | D9: 08
A10: Sample | B10: SMP-2026-00001 | C10: Quotation line, courier, test and approval | D10: 11
A11: Comparative statement | B11: CS-2026-00001 | C11: Normalized offer versions, assumptions | D11: 10
A12: Negotiation round | B12: NEG-2026-00001 | C12: Original / revised commercial terms | D12: 13
A13: Award package | B13: AWD-2026-00001 | C13: Recommended supplier, cost and approval trail | D13: 14
A14: Purchase order | B14: PO-2026-00001 | C14: Frozen approval snapshot, PDF revision and send log | D14: 18
A15: Proforma invoice | B15: PI-2026-00001 | C15: Supplier PI reference, match exceptions | D15: 21
A16: Change / exception case | B16: EXC-2026-00001 | C16: Type, owner, severity, resolution, audit evidence | D16: Any

Sheet Open Policy Items
A1: Open Policy Items — decisions OIL must confirm before the specification is final
A2: Orange cells are for OIL to complete. Nothing has been pre-filled: owners, outcomes and dates are not stated in the specification.
A4: No. | B4: Policy decision | C4: Decision owner | D4: Decision / outcome | E4: Target date | F4: Status
A5: 1 | B5: Procurement authority matrix and approval thresholds (including whether the ultimate approval title is ED, MD or authorized delegate) | F5: Open
A6: 2 | B6: Whether the counting convention for China RFQ deadlines excludes the invitation date in every circumstance | F6: Open
A7: 3 | B7: Default closing hour and whether supplier calendars are chosen per supplier or per RFQ | F7: Open
A8: 4 | B8: Sample mandatory / waiver criteria by RM type and acceptable deviations / tolerances | F8: Open
A9: 5 | B9: Vendor prequalification, quotation confidentiality and bid-opening policy | F9: Open
A10: 6 | B10: RFQ extensions, re-tendering, emergency sourcing and single-source approval rights | F10: Open
A11: 7 | B11: Supplier performance scoring weights and tie-break logic | F11: Open
A12: 8 | B12: PO acknowledgment SLA, PO cancellation and PO amendment authority | F12: Open
A13: 9 | B13: Freight, FX and landed-cost standard assumptions, including bank / finance charges | F13: Open
A14: 10 | B14: Finance three-way-match tolerances, advance-payment policy and invoice settlement controls | F14: Open
A15: 11 | B15: Required documents, mandatory legal terms and standard supplier PO clauses | F15: Open
A16: 12 | B16: ERP / email / bank integrations, data migration, retention and operating support owners | F16: Open
B18: Items still open | F18: =COUNTIF(F5:F16,"Open") -> 12
B19: Items confirmed | F19: =COUNTIF(F5:F16,"Confirmed") -> 0
